<sdf version='1.7'>
  <model name='ridgeback'>
    <link name='base_link'>
      <inertial>
        <pose>-0.004639 0.001543 0.071661 0 -0 0</pose>
        <mass>181.672</mass>
        <inertia>
          <ixx>6.20818</ixx>
          <ixy>-0.00807328</ixy>
          <ixz>0.183193</ixz>
          <iyy>6.248</iyy>
          <iyz>0.0399682</iyz>
          <izz>9.16346</izz>
        </inertia>
      </inertial>
      <collision name='base_link_fixed_joint_lump__chassis_link_collision'>
        <pose>0 0 0.35 0 -0 0</pose>
        <geometry>
          <box>
            <size>0.55 0.44 0.2</size>
          </box>
        </geometry>
        <surface>
          <contact>
            <ode/>
          </contact>
          <friction>
            <ode/>
          </friction>
        </surface>
      </collision>
      <collision name='base_link_fixed_joint_lump__center_laser_collision_1'>
        <pose>0 0 0.25 0 -0 0</pose>
        <geometry>
          <box>
            <size>0.105 0.1 0.1</size>
          </box>
        </geometry>
        <surface>
          <contact>
            <ode/>
          </contact>
          <friction>
            <ode/>
          </friction>
        </surface>
      </collision>
      <visual name='base_link_fixed_joint_lump__chassis_link_visual'>
        <pose>0 0 0 0 -0 0</pose>
        <geometry>
          <mesh>
            <scale>1 1 1</scale>
            <uri>model://ridgeback_description/meshes/body_without_light.STL</uri>
          </mesh>
        </geometry>
        <material>
          <script>
            <name>Gazebo/DarkGrey</name>
            <uri>file://media/materials/scripts/gazebo.material</uri>
          </script>
        </material>
      </visual>
      <visual name='base_link_fixed_joint_lump__center_laser_visual_1'>
        <pose>0 0 0.3 0 -0 0</pose>
        <geometry>
          <mesh>
            <scale>1 1 1</scale>
            <uri>model://lms1xx/meshes/sick-lms1xx.dae</uri>
          </mesh>
        </geometry>
      </visual>
      <gravity>0</gravity>
      <sensor name='center_laser' type='ray'>
        <visualize>0</visualize>
        <update_rate>20</update_rate>
        <ray>
          <scan>
            <horizontal>
              <samples>720</samples>
              <resolution>1</resolution>
              <min_angle>-3.14159</min_angle>
              <max_angle>3.14159</max_angle>
            </horizontal>
          </scan>
          <range>
            <min>0.45</min>
            <max>30</max>
            <resolution>0.01</resolution>
          </range>
          <noise>
            <type>gaussian</type>
            <mean>0</mean>
            <stddev>0.001</stddev>
          </noise>
        </ray>
        <plugin name='gazebo_ros_laser' filename='libgazebo_ros_laser.so'>
          <topicName>scan</topicName>
          <frameName>center_laser</frameName>
          <robotNamespace>jacakal</robotNamespace>
        </plugin>
        <pose>0 0 0.3 0 -0 0</pose>
      </sensor>
    </link>
    <joint name='front_rocker' type='revolute'>
      <pose relative_to='base_link'>0.212 0 0.05 0 -0 0</pose>
      <parent>base_link</parent>
      <child>front_rocker_link</child>
      <axis>
        <xyz>1 0 0</xyz>
        <limit>
          <lower>-0.08726</lower>
          <upper>0.08726</upper>
          <effort>0</effort>
          <velocity>0</velocity>
        </limit>
        <dynamics>
          <spring_reference>0</spring_reference>
          <spring_stiffness>0</spring_stiffness>
        </dynamics>
      </axis>
    </joint>
    <link name='front_rocker_link'>
      <pose relative_to='front_rocker'>0 0 0 0 -0 0</pose>
      <inertial>
        <pose>0 0 0 1.5708 -0 1.5708</pose>
        <mass>10.267</mass>
        <inertia>
          <ixx>0.0288</ixx>
          <ixy>2.20484e-06</ixy>
          <ixz>-1.3145e-05</ixz>
          <iyy>0.4324</iyy>
          <iyz>0.0018944</iyz>
          <izz>0.413</izz>
        </inertia>
      </inertial>
    </link>
    <joint name='front_left_wheel' type='revolute'>
      <pose relative_to='front_rocker_link'>-0.005 0.21 0.03 0 -0 0</pose>
      <parent>front_rocker_link</parent>
      <child>front_left_wheel_link</child>
      <axis>
        <xyz>0 1 0</xyz>
        <limit>
          <lower>-1e+16</lower>
          <upper>1e+16</upper>
        </limit>
        <dynamics>
          <spring_reference>0</spring_reference>
          <spring_stiffness>0</spring_stiffness>
        </dynamics>
      </axis>
    </joint>
    <link name='front_left_wheel_link'>
      <pose relative_to='front_left_wheel'>0 0 0 0 -0 0</pose>
      <inertial>
        <pose>0 0 0 0 -0 0</pose>
        <mass>2.3</mass>
        <inertia>
          <ixx>0.0033212</ixx>
          <ixy>0</ixy>
          <ixz>0</ixz>
          <iyy>0.0066424</iyy>
          <iyz>0</iyz>
          <izz>0.0033212</izz>
        </inertia>
      </inertial>
      <collision name='front_left_wheel_link_collision'>
        <pose>0 -0.01 0 1.5708 -0 0</pose>
        <geometry>
          <cylinder>
            <length>0.04</length>
            <radius>0.07</radius>
          </cylinder>
        </geometry>
        <surface>
          <contact>
            <ode/>
          </contact>
          <friction>
            <ode>
              <mu>0</mu>
              <mu2>0</mu2>
            </ode>
          </friction>
        </surface>
      </collision>
      <visual name='front_left_wheel_link_visual'>
        <pose>0 0 0 0 -0 0</pose>
        <geometry>
          <mesh>
            <scale>1 1 1</scale>
            <uri>model://ridgeback_description/meshes/wheel_new.STL</uri>
          </mesh>
        </geometry>
        <material>
          <script>
            <name>Gazebo/DarkGrey</name>
            <uri>file://media/materials/scripts/gazebo.material</uri>
          </script>
        </material>
      </visual>
    </link>
    <joint name='front_right_wheel' type='revolute'>
      <pose relative_to='front_rocker_link'>-0.005 -0.18 0.03 0 -0 0</pose>
      <parent>front_rocker_link</parent>
      <child>front_right_wheel_link</child>
      <axis>
        <xyz>0 1 0</xyz>
        <limit>
          <lower>-1e+16</lower>
          <upper>1e+16</upper>
        </limit>
        <dynamics>
          <spring_reference>0</spring_reference>
          <spring_stiffness>0</spring_stiffness>
        </dynamics>
      </axis>
    </joint>
    <link name='front_right_wheel_link'>
      <pose relative_to='front_right_wheel'>0 0 0 0 -0 0</pose>
      <inertial>
        <pose>0 0 0 0 -0 0</pose>
        <mass>2.3</mass>
        <inertia>
          <ixx>0.0033212</ixx>
          <ixy>0</ixy>
          <ixz>0</ixz>
          <iyy>0.0066424</iyy>
          <iyz>0</iyz>
          <izz>0.0033212</izz>
        </inertia>
      </inertial>
      <collision name='front_right_wheel_link_collision'>
        <pose>0 -0.01 0 1.5708 -0 0</pose>
        <geometry>
          <cylinder>
            <length>0.04</length>
            <radius>0.07</radius>
          </cylinder>
        </geometry>
        <surface>
          <contact>
            <ode/>
          </contact>
          <friction>
            <ode>
              <mu>0</mu>
              <mu2>0</mu2>
            </ode>
          </friction>
        </surface>
      </collision>
      <visual name='front_right_wheel_link_visual'>
        <pose>0 0 0 0 -0 0</pose>
        <geometry>
          <mesh>
            <scale>1 1 1</scale>
            <uri>model://ridgeback_description/meshes/wheel_new.STL</uri>
          </mesh>
        </geometry>
        <material>
          <script>
            <name>Gazebo/DarkGrey</name>
            <uri>file://media/materials/scripts/gazebo.material</uri>
          </script>
        </material>
      </visual>
    </link>
    <joint name='rear_left_wheel' type='revolute'>
      <pose relative_to='base_link'>-0.217 0.21 0.08 0 -0 0</pose>
      <parent>base_link</parent>
      <child>rear_left_wheel_link</child>
      <axis>
        <xyz>0 1 0</xyz>
        <limit>
          <lower>-1e+16</lower>
          <upper>1e+16</upper>
        </limit>
        <dynamics>
          <spring_reference>0</spring_reference>
          <spring_stiffness>0</spring_stiffness>
        </dynamics>
      </axis>
    </joint>
    <link name='rear_left_wheel_link'>
      <pose relative_to='rear_left_wheel'>0 0 0 0 -0 0</pose>
      <inertial>
        <pose>0 0 0 0 -0 0</pose>
        <mass>2.3</mass>
        <inertia>
          <ixx>0.0033212</ixx>
          <ixy>0</ixy>
          <ixz>0</ixz>
          <iyy>0.0066424</iyy>
          <iyz>0</iyz>
          <izz>0.0033212</izz>
        </inertia>
      </inertial>
      <collision name='rear_left_wheel_link_collision'>
        <pose>0 -0.01 0 1.5708 -0 0</pose>
        <geometry>
          <cylinder>
            <length>0.04</length>
            <radius>0.07</radius>
          </cylinder>
        </geometry>
        <surface>
          <contact>
            <ode/>
          </contact>
          <friction>
            <ode>
              <mu>0</mu>
              <mu2>0</mu2>
            </ode>
          </friction>
        </surface>
      </collision>
      <visual name='rear_left_wheel_link_visual'>
        <pose>0 0 0 0 -0 0</pose>
        <geometry>
          <mesh>
            <scale>1 1 1</scale>
            <uri>model://ridgeback_description/meshes/wheel_new.STL</uri>
          </mesh>
        </geometry>
        <material>
          <script>
            <name>Gazebo/DarkGrey</name>
            <uri>file://media/materials/scripts/gazebo.material</uri>
          </script>
        </material>
      </visual>
    </link>
    <joint name='rear_right_wheel' type='revolute'>
      <pose relative_to='base_link'>-0.217 -0.18 0.08 0 -0 0</pose>
      <parent>base_link</parent>
      <child>rear_right_wheel_link</child>
      <axis>
        <xyz>0 1 0</xyz>
        <limit>
          <lower>-1e+16</lower>
          <upper>1e+16</upper>
        </limit>
        <dynamics>
          <spring_reference>0</spring_reference>
          <spring_stiffness>0</spring_stiffness>
        </dynamics>
      </axis>
    </joint>
    <link name='rear_right_wheel_link'>
      <pose relative_to='rear_right_wheel'>0 0 0 0 -0 0</pose>
      <inertial>
        <pose>0 0 0 0 -0 0</pose>
        <mass>2.3</mass>
        <inertia>
          <ixx>0.0033212</ixx>
          <ixy>0</ixy>
          <ixz>0</ixz>
          <iyy>0.0066424</iyy>
          <iyz>0</iyz>
          <izz>0.0033212</izz>
        </inertia>
      </inertial>
      <collision name='rear_right_wheel_link_collision'>
        <pose>0 -0.01 0 1.5708 -0 0</pose>
        <geometry>
          <cylinder>
            <length>0.04</length>
            <radius>0.07</radius>
          </cylinder>
        </geometry>
        <surface>
          <contact>
            <ode/>
          </contact>
          <friction>
            <ode>
              <mu>0</mu>
              <mu2>0</mu2>
            </ode>
          </friction>
        </surface>
      </collision>
      <visual name='rear_right_wheel_link_visual'>
        <pose>0 0 0 0 -0 0</pose>
        <geometry>
          <mesh>
            <scale>1 1 1</scale>
            <uri>model://ridgeback_description/meshes/wheel_new.STL</uri>
          </mesh>
        </geometry>
        <material>
          <script>
            <name>Gazebo/DarkGrey</name>
            <uri>file://media/materials/scripts/gazebo.material</uri>
          </script>
        </material>
      </visual>
    </link>
    <joint name='front_camera_pivot_joint' type='revolute'>
      <pose relative_to='base_link'>0.01 -0.008 0.228 0 -0 0</pose>
      <parent>base_link</parent>
      <child>front_camera_beam</child>
      <axis>
        <xyz>0 0 1</xyz>
        <limit>
          <lower>-1.5707</lower>
          <upper>1.5707</upper>
          <effort>2</effort>
          <velocity>10</velocity>
        </limit>
        <dynamics>
          <spring_reference>0</spring_reference>
          <spring_stiffness>0</spring_stiffness>
        </dynamics>
      </axis>
    </joint>
    <link name='front_camera_beam'>
      <pose relative_to='front_camera_pivot_joint'>0 0 0 0 -0 0</pose>
      <inertial>
        <pose>0 0 0 0 -0 0</pose>
        <mass>0.98307</mass>
        <inertia>
          <ixx>0.0072228</ixx>
          <ixy>1.8624e-07</ixy>
          <ixz>5.1373e-07</ixz>
          <iyy>0.0035103</iyy>
          <iyz>-0.0016193</iyz>
          <izz>0.00443</izz>
        </inertia>
      </inertial>
      <visual name='front_camera_beam_fixed_joint_lump__front_camera_visual'>
        <pose>0 0 0.1 0 -0 0</pose>
        <geometry>
          <mesh>
            <scale>1 1 1</scale>
            <uri>model://ridgeback_description/meshes/gun_new.STL</uri>
          </mesh>
        </geometry>
        <material>
          <script>
            <name>Gazebo/DarkGrey</name>
            <uri>file://media/materials/scripts/gazebo.material</uri>
          </script>
        </material>
      </visual>
      <sensor name='front' type='camera'>
        <update_rate>60</update_rate>
        <camera name='front'>
          <pose>0 0 0 0 -1.5707 1.5707</pose>
          <horizontal_fov>1.0472</horizontal_fov>
          <image>
            <width>640</width>
            <height>512</height>
            <format>R8G8B8</format>
          </image>
          <clip>
            <near>0.5</near>
            <far>300</far>
          </clip>
          <noise>
            <type>gaussian</type>
            <mean>0</mean>
            <stddev>0.007</stddev>
          </noise>
        </camera>
        <plugin name='camera_controller' filename='libgazebo_ros_camera.so'>
          <alwaysOn>1</alwaysOn>
          <updateRate>60</updateRate>
          <cameraName>front</cameraName>
          <imageTopicName>image_raw</imageTopicName>
          <cameraInfoTopicName>camera_info</cameraInfoTopicName>
          <frameName>front_camera_optical</frameName>
          <hackBaseline>0.07</hackBaseline>
          <distortionK1>0.0</distortionK1>
          <distortionK2>0.0</distortionK2>
          <distortionK3>0.0</distortionK3>
          <distortionT1>0.0</distortionT1>
          <distortionT2>0.0</distortionT2>
        </plugin>
        <pose>0 0 0 -1.5708 -0 -1.5708</pose>
      </sensor>
    </link>
    <static>0</static>
    <plugin name='gazebo_ros_control' filename='libgazebo_ros_control.so'>
      <robotNamespace>/jacakal</robotNamespace>
    </plugin>
    <plugin name='gazebo_ros_joint_pose_trajectory' filename='libgazebo_ros_joint_pose_trajectory.so'>
      <robotNamespace>/jacakal</robotNamespace>
      <updateRate>100</updateRate>
    </plugin>
    <plugin name='ridgeback_ros_force_based_move' filename='libridgeback_ros_force_based_move.so'>
      <robotNamespace>/jacakal</robotNamespace>
      <commandTopic>cmd_vel</commandTopic>
      <odometryTopic>odom</odometryTopic>
      <odometryFrame>odom</odometryFrame>
      <odometryRate>25.0</odometryRate>
      <robotBaseFrame>base_link</robotBaseFrame>
      <cmdVelTimeOut>0.25</cmdVelTimeOut>
      <publishOdometryTf>0</publishOdometryTf>
      <yaw_velocity_p_gain>500.0</yaw_velocity_p_gain>
      <x_velocity_p_gain>10000.0</x_velocity_p_gain>
      <y_velocity_p_gain>10000.0</y_velocity_p_gain>
    </plugin>
    <plugin name='imu_controller' filename='libhector_gazebo_ros_imu.so'>
      <robotNamespace>/jacakal</robotNamespace>
      <updateRate>50.0</updateRate>
      <topicName>imu/data</topicName>
      <frameId>jacakal/base_link</frameId>
      <accelDrift>0.005 0.005 0.005</accelDrift>
      <accelGaussianNoise>0.005 0.005 0.005</accelGaussianNoise>
      <rateDrift>0.00005 0.00005 0.00005</rateDrift>
      <rateGaussianNoise>0.00005 0.00005 0.00005</rateGaussianNoise>
      <headingDrift>0.005</headingDrift>
      <headingGaussianNoise>0.005</headingGaussianNoise>
      <bodyName>base_link</bodyName>
      <xyzOffset>0.2085 -0.2902 0.1681</xyzOffset>
      <rpyOffset>0 -0 0</rpyOffset>
      <ignition::corrected_offsets>1</ignition::corrected_offsets>
    </plugin>
    <plugin name='gazebo_ros_joint_state_publisher' filename='libgazebo_ros_joint_state_publisher.so'>
      <jointName>front_rocker</jointName>
      <robotNamespace>/jacakal</robotNamespace>
      <updateRate>50.0</updateRate>
    </plugin>
  </model>
</sdf>
